<?xml version="1.0"?>
<robot name="simple_revolute_robot">

  <!-- Base Link -->
  <link name="base_link">
    <visual>
      <geometry>
        <box size="0.1 0.1 0.1"/>
      </geometry>
      <origin xyz="0 0 0" rpy="0 0 0"/>
      <material name="gray">
        <color rgba="0.5 0.5 0.5 1"/>
      </material>
    </visual>
  </link>

  <!-- Arm Link -->
  <link name="arm_link">
    <visual>
      <geometry>
        <box size="0.2 0.05 0.05"/>
      </geometry>
      <origin xyz="0.1 0 0" rpy="0 0 0"/>
      <material name="blue">
        <color rgba="0 0 1 1"/>
      </material>
    </visual>
  </link>

  <!-- End Effector Link -->
  <link name="end_effector_link">
    <visual>
      <geometry>
        <cylinder radius="0.02" length="0.1"/>
      </geometry>
      <origin xyz="0 0 0.05" rpy="0 0 0"/>
      <material name="red">
        <color rgba="1 0 0 1"/>
      </material>
    </visual>
  </link>

  <!-- Revolute Joint (rotates around Z-axis) -->
  <joint name="revolute_joint" type="revolute">
    <parent link="base_link"/>
    <child link="arm_link"/>
    <origin xyz="0 0 0.05" rpy="0 0 0"/>
    <axis xyz="0 0 1"/>
    <limit lower="-3.14159" upper="3.14159" effort="1000" velocity="1.0"/>
  </joint>

  <!-- Fixed Joint to end effector -->
  <joint name="end_effector_joint" type="fixed">
    <parent link="arm_link"/>
    <child link="end_effector_link"/>
    <origin xyz="0.2 0 0" rpy="0 0 0"/>
  </joint>

</robot>